{
 "cells": [
  {
   "cell_type": "code",
   "execution_count": 1,
   "id": "4d7d180c-fcc7-41fc-9e6e-568f419213bd",
   "metadata": {},
   "outputs": [
    {
     "name": "stdout",
     "output_type": "stream",
     "text": [
      "Dataset split into training and testing sets.\n",
      "Found 2329 images belonging to 4 classes.\n",
      "Found 581 images belonging to 4 classes.\n",
      "Found 729 images belonging to 4 classes.\n",
      "Class indices: {'AD': 0, 'CN': 1, 'EMCI': 2, 'LMCI': 3}\n"
     ]
    },
    {
     "name": "stderr",
     "output_type": "stream",
     "text": [
      "/opt/anaconda3/envs/tf_env/lib/python3.9/site-packages/keras/src/layers/convolutional/base_conv.py:107: UserWarning: Do not pass an `input_shape`/`input_dim` argument to a layer. When using Sequential models, prefer using an `Input(shape)` object as the first layer in the model instead.\n",
      "  super().__init__(activity_regularizer=activity_regularizer, **kwargs)\n",
      "2024-11-11 13:21:50.714447: I metal_plugin/src/device/metal_device.cc:1154] Metal device set to: Apple M2\n",
      "2024-11-11 13:21:50.718650: I metal_plugin/src/device/metal_device.cc:296] systemMemory: 8.00 GB\n",
      "2024-11-11 13:21:50.720652: I metal_plugin/src/device/metal_device.cc:313] maxCacheSize: 2.67 GB\n",
      "2024-11-11 13:21:50.726948: I tensorflow/core/common_runtime/pluggable_device/pluggable_device_factory.cc:305] Could not identify NUMA node of platform GPU ID 0, defaulting to 0. Your kernel may not have been built with NUMA support.\n",
      "2024-11-11 13:21:50.726976: I tensorflow/core/common_runtime/pluggable_device/pluggable_device_factory.cc:271] Created TensorFlow device (/job:localhost/replica:0/task:0/device:GPU:0 with 0 MB memory) -> physical PluggableDevice (device: 0, name: METAL, pci bus id: <undefined>)\n"
     ]
    },
    {
     "name": "stdout",
     "output_type": "stream",
     "text": [
      "Epoch 1/10\n"
     ]
    },
    {
     "name": "stderr",
     "output_type": "stream",
     "text": [
      "2024-11-11 13:21:54.339670: I tensorflow/core/grappler/optimizers/custom_graph_optimizer_registry.cc:117] Plugin optimizer for device_type GPU is enabled.\n",
      "/opt/anaconda3/envs/tf_env/lib/python3.9/site-packages/keras/src/trainers/data_adapters/py_dataset_adapter.py:121: UserWarning: Your `PyDataset` class should call `super().__init__(**kwargs)` in its constructor. `**kwargs` can include `workers`, `use_multiprocessing`, `max_queue_size`. Do not pass these arguments to `fit()`, as they will be ignored.\n",
      "  self._warn_if_super_not_called()\n"
     ]
    },
    {
     "name": "stdout",
     "output_type": "stream",
     "text": [
      "\u001b[1m72/72\u001b[0m \u001b[32m━━━━━━━━━━━━━━━━━━━━\u001b[0m\u001b[37m\u001b[0m \u001b[1m118s\u001b[0m 1s/step - accuracy: 0.2693 - loss: nan - val_accuracy: 0.2517 - val_loss: nan\n",
      "Epoch 2/10\n",
      "\u001b[1m72/72\u001b[0m \u001b[32m━━━━━━━━━━━━━━━━━━━━\u001b[0m\u001b[37m\u001b[0m \u001b[1m0s\u001b[0m 3ms/step - accuracy: 0.0938 - loss: nan - val_accuracy: 0.0000e+00 - val_loss: nan\n",
      "Epoch 3/10\n"
     ]
    },
    {
     "name": "stderr",
     "output_type": "stream",
     "text": [
      "2024-11-11 13:23:52.668807: W tensorflow/core/framework/local_rendezvous.cc:404] Local rendezvous is aborting with status: OUT_OF_RANGE: End of sequence\n",
      "\t [[{{node IteratorGetNext}}]]\n",
      "2024-11-11 13:23:52.668838: W tensorflow/core/framework/local_rendezvous.cc:404] Local rendezvous is aborting with status: OUT_OF_RANGE: End of sequence\n",
      "\t [[{{node IteratorGetNext}}]]\n",
      "\t [[StatefulPartitionedCall/adam/add_14/_52]]\n",
      "2024-11-11 13:23:52.668865: I tensorflow/core/framework/local_rendezvous.cc:422] Local rendezvous recv item cancelled. Key hash: 7636598271967014755\n",
      "2024-11-11 13:23:52.668875: I tensorflow/core/framework/local_rendezvous.cc:422] Local rendezvous recv item cancelled. Key hash: 15162237694967042485\n",
      "2024-11-11 13:23:52.668878: I tensorflow/core/framework/local_rendezvous.cc:422] Local rendezvous recv item cancelled. Key hash: 16157401480198025417\n",
      "2024-11-11 13:23:52.668881: I tensorflow/core/framework/local_rendezvous.cc:422] Local rendezvous recv item cancelled. Key hash: 13358348135542482143\n",
      "2024-11-11 13:23:52.668884: I tensorflow/core/framework/local_rendezvous.cc:422] Local rendezvous recv item cancelled. Key hash: 247987022651512771\n",
      "2024-11-11 13:23:52.668886: I tensorflow/core/framework/local_rendezvous.cc:422] Local rendezvous recv item cancelled. Key hash: 8536117531415427311\n",
      "2024-11-11 13:23:52.668891: I tensorflow/core/framework/local_rendezvous.cc:422] Local rendezvous recv item cancelled. Key hash: 13984501884745206167\n",
      "2024-11-11 13:23:52.668894: I tensorflow/core/framework/local_rendezvous.cc:422] Local rendezvous recv item cancelled. Key hash: 9721505157672200855\n",
      "2024-11-11 13:23:52.668902: I tensorflow/core/framework/local_rendezvous.cc:422] Local rendezvous recv item cancelled. Key hash: 10641088503048191638\n",
      "2024-11-11 13:23:52.668912: I tensorflow/core/framework/local_rendezvous.cc:422] Local rendezvous recv item cancelled. Key hash: 5081133311757591444\n",
      "2024-11-11 13:23:52.668916: I tensorflow/core/framework/local_rendezvous.cc:422] Local rendezvous recv item cancelled. Key hash: 16426361773769575293\n",
      "2024-11-11 13:23:52.668934: I tensorflow/core/framework/local_rendezvous.cc:422] Local rendezvous recv item cancelled. Key hash: 8771219597739304216\n",
      "2024-11-11 13:23:52.668936: I tensorflow/core/framework/local_rendezvous.cc:422] Local rendezvous recv item cancelled. Key hash: 9778036480873716785\n",
      "2024-11-11 13:23:52.668942: I tensorflow/core/framework/local_rendezvous.cc:422] Local rendezvous recv item cancelled. Key hash: 9585094191913983771\n",
      "2024-11-11 13:23:52.668946: I tensorflow/core/framework/local_rendezvous.cc:422] Local rendezvous recv item cancelled. Key hash: 7260992625463388466\n",
      "2024-11-11 13:23:52.669737: I tensorflow/core/framework/local_rendezvous.cc:422] Local rendezvous recv item cancelled. Key hash: 15992414456365902956\n",
      "2024-11-11 13:23:52.669745: I tensorflow/core/framework/local_rendezvous.cc:422] Local rendezvous recv item cancelled. Key hash: 12247300843013860802\n",
      "2024-11-11 13:23:52.669748: I tensorflow/core/framework/local_rendezvous.cc:422] Local rendezvous recv item cancelled. Key hash: 11326548799269588624\n",
      "2024-11-11 13:23:52.669750: I tensorflow/core/framework/local_rendezvous.cc:422] Local rendezvous recv item cancelled. Key hash: 12129038999192260608\n",
      "2024-11-11 13:23:52.669753: I tensorflow/core/framework/local_rendezvous.cc:422] Local rendezvous recv item cancelled. Key hash: 17537048164691407110\n",
      "2024-11-11 13:23:52.669755: I tensorflow/core/framework/local_rendezvous.cc:422] Local rendezvous recv item cancelled. Key hash: 10519956363398026286\n",
      "2024-11-11 13:23:52.669762: I tensorflow/core/framework/local_rendezvous.cc:422] Local rendezvous recv item cancelled. Key hash: 5945813602355043242\n",
      "/opt/anaconda3/envs/tf_env/lib/python3.9/contextlib.py:137: UserWarning: Your input ran out of data; interrupting training. Make sure that your dataset or generator can generate at least `steps_per_epoch * epochs` batches. You may need to use the `.repeat()` function when building your dataset.\n",
      "  self.gen.throw(typ, value, traceback)\n",
      "2024-11-11 13:23:52.669766: I tensorflow/core/framework/local_rendezvous.cc:422] Local rendezvous recv item cancelled. Key hash: 14377770143127862722\n",
      "2024-11-11 13:23:52.669769: I tensorflow/core/framework/local_rendezvous.cc:422] Local rendezvous recv item cancelled. Key hash: 5061393342076599618\n",
      "2024-11-11 13:23:52.669771: I tensorflow/core/framework/local_rendezvous.cc:422] Local rendezvous recv item cancelled. Key hash: 11662092417062838046\n",
      "2024-11-11 13:23:52.852475: W tensorflow/core/framework/local_rendezvous.cc:404] Local rendezvous is aborting with status: OUT_OF_RANGE: End of sequence\n",
      "\t [[{{node IteratorGetNext}}]]\n",
      "2024-11-11 13:23:52.852487: W tensorflow/core/framework/local_rendezvous.cc:404] Local rendezvous is aborting with status: OUT_OF_RANGE: End of sequence\n",
      "\t [[{{node IteratorGetNext}}]]\n",
      "\t [[ArgMax/_6]]\n",
      "2024-11-11 13:23:52.852492: I tensorflow/core/framework/local_rendezvous.cc:422] Local rendezvous recv item cancelled. Key hash: 4560231222405327209\n",
      "2024-11-11 13:23:52.852495: I tensorflow/core/framework/local_rendezvous.cc:422] Local rendezvous recv item cancelled. Key hash: 11888865570258885543\n",
      "2024-11-11 13:23:52.852498: I tensorflow/core/framework/local_rendezvous.cc:422] Local rendezvous recv item cancelled. Key hash: 4927899215993160537\n",
      "2024-11-11 13:23:52.852500: I tensorflow/core/framework/local_rendezvous.cc:422] Local rendezvous recv item cancelled. Key hash: 7186300053530939115\n",
      "2024-11-11 13:23:52.852503: I tensorflow/core/framework/local_rendezvous.cc:422] Local rendezvous recv item cancelled. Key hash: 8576401013533392477\n",
      "2024-11-11 13:23:52.852508: I tensorflow/core/framework/local_rendezvous.cc:422] Local rendezvous recv item cancelled. Key hash: 6653790227565728300\n"
     ]
    },
    {
     "name": "stdout",
     "output_type": "stream",
     "text": [
      "\u001b[1m52/72\u001b[0m \u001b[32m━━━━━━━━━━━━━━\u001b[0m\u001b[37m━━━━━━\u001b[0m \u001b[1m25s\u001b[0m 1s/step - accuracy: 0.2413 - loss: nan"
     ]
    },
    {
     "name": "stderr",
     "output_type": "stream",
     "text": [
      "2024-11-11 13:25:08.962282: W tensorflow/core/framework/op_kernel.cc:1827] UNKNOWN: FileNotFoundError: [Errno 2] No such file or directory: '/Users/code/alzheimerDetect/split_dataset_axial/train/LMCI/Screenshot 2024-08-05 021551.png'\n",
      "Traceback (most recent call last):\n",
      "\n",
      "  File \"/opt/anaconda3/envs/tf_env/lib/python3.9/site-packages/tensorflow/python/ops/script_ops.py\", line 270, in __call__\n",
      "    ret = func(*args)\n",
      "\n",
      "  File \"/opt/anaconda3/envs/tf_env/lib/python3.9/site-packages/tensorflow/python/autograph/impl/api.py\", line 643, in wrapper\n",
      "    return func(*args, **kwargs)\n",
      "\n",
      "  File \"/opt/anaconda3/envs/tf_env/lib/python3.9/site-packages/tensorflow/python/data/ops/from_generator_op.py\", line 198, in generator_py_func\n",
      "    values = next(generator_state.get_iterator(iterator_id))\n",
      "\n",
      "  File \"/opt/anaconda3/envs/tf_env/lib/python3.9/site-packages/keras/src/trainers/data_adapters/py_dataset_adapter.py\", line 260, in _get_iterator\n",
      "    for i, batch in enumerate(gen_fn()):\n",
      "\n",
      "  File \"/opt/anaconda3/envs/tf_env/lib/python3.9/site-packages/keras/src/trainers/data_adapters/py_dataset_adapter.py\", line 253, in generator_fn\n",
      "    yield self.py_dataset[i]\n",
      "\n",
      "  File \"/opt/anaconda3/envs/tf_env/lib/python3.9/site-packages/keras/src/legacy/preprocessing/image.py\", line 68, in __getitem__\n",
      "    return self._get_batches_of_transformed_samples(index_array)\n",
      "\n",
      "  File \"/opt/anaconda3/envs/tf_env/lib/python3.9/site-packages/keras/src/legacy/preprocessing/image.py\", line 313, in _get_batches_of_transformed_samples\n",
      "    img = image_utils.load_img(\n",
      "\n",
      "  File \"/opt/anaconda3/envs/tf_env/lib/python3.9/site-packages/keras/src/utils/image_utils.py\", line 235, in load_img\n",
      "    with open(path, \"rb\") as f:\n",
      "\n",
      "FileNotFoundError: [Errno 2] No such file or directory: '/Users/code/alzheimerDetect/split_dataset_axial/train/LMCI/Screenshot 2024-08-05 021551.png'\n",
      "\n",
      "\n",
      "2024-11-11 13:25:09.060195: W tensorflow/core/framework/local_rendezvous.cc:404] Local rendezvous is aborting with status: UNKNOWN: FileNotFoundError: [Errno 2] No such file or directory: '/Users/code/alzheimerDetect/split_dataset_axial/train/LMCI/Screenshot 2024-08-05 021551.png'\n",
      "Traceback (most recent call last):\n",
      "\n",
      "  File \"/opt/anaconda3/envs/tf_env/lib/python3.9/site-packages/tensorflow/python/ops/script_ops.py\", line 270, in __call__\n",
      "    ret = func(*args)\n",
      "\n",
      "  File \"/opt/anaconda3/envs/tf_env/lib/python3.9/site-packages/tensorflow/python/autograph/impl/api.py\", line 643, in wrapper\n",
      "    return func(*args, **kwargs)\n",
      "\n",
      "  File \"/opt/anaconda3/envs/tf_env/lib/python3.9/site-packages/tensorflow/python/data/ops/from_generator_op.py\", line 198, in generator_py_func\n",
      "    values = next(generator_state.get_iterator(iterator_id))\n",
      "\n",
      "  File \"/opt/anaconda3/envs/tf_env/lib/python3.9/site-packages/keras/src/trainers/data_adapters/py_dataset_adapter.py\", line 260, in _get_iterator\n",
      "    for i, batch in enumerate(gen_fn()):\n",
      "\n",
      "  File \"/opt/anaconda3/envs/tf_env/lib/python3.9/site-packages/keras/src/trainers/data_adapters/py_dataset_adapter.py\", line 253, in generator_fn\n",
      "    yield self.py_dataset[i]\n",
      "\n",
      "  File \"/opt/anaconda3/envs/tf_env/lib/python3.9/site-packages/keras/src/legacy/preprocessing/image.py\", line 68, in __getitem__\n",
      "    return self._get_batches_of_transformed_samples(index_array)\n",
      "\n",
      "  File \"/opt/anaconda3/envs/tf_env/lib/python3.9/site-packages/keras/src/legacy/preprocessing/image.py\", line 313, in _get_batches_of_transformed_samples\n",
      "    img = image_utils.load_img(\n",
      "\n",
      "  File \"/opt/anaconda3/envs/tf_env/lib/python3.9/site-packages/keras/src/utils/image_utils.py\", line 235, in load_img\n",
      "    with open(path, \"rb\") as f:\n",
      "\n",
      "FileNotFoundError: [Errno 2] No such file or directory: '/Users/code/alzheimerDetect/split_dataset_axial/train/LMCI/Screenshot 2024-08-05 021551.png'\n",
      "\n",
      "\n",
      "\t [[{{node PyFunc}}]]\n",
      "\t [[IteratorGetNext]]\n",
      "2024-11-11 13:25:09.060212: I tensorflow/core/framework/local_rendezvous.cc:422] Local rendezvous recv item cancelled. Key hash: 5061393342076599618\n",
      "2024-11-11 13:25:09.060216: I tensorflow/core/framework/local_rendezvous.cc:422] Local rendezvous recv item cancelled. Key hash: 5081133311757591444\n",
      "2024-11-11 13:25:09.060224: I tensorflow/core/framework/local_rendezvous.cc:422] Local rendezvous recv item cancelled. Key hash: 8771219597739304216\n",
      "2024-11-11 13:25:09.060226: I tensorflow/core/framework/local_rendezvous.cc:422] Local rendezvous recv item cancelled. Key hash: 7260992625463388466\n",
      "2024-11-11 13:25:09.060229: I tensorflow/core/framework/local_rendezvous.cc:422] Local rendezvous recv item cancelled. Key hash: 15992414456365902956\n",
      "2024-11-11 13:25:09.060231: I tensorflow/core/framework/local_rendezvous.cc:422] Local rendezvous recv item cancelled. Key hash: 12247300843013860802\n",
      "2024-11-11 13:25:09.060233: I tensorflow/core/framework/local_rendezvous.cc:422] Local rendezvous recv item cancelled. Key hash: 11326548799269588624\n",
      "2024-11-11 13:25:09.060236: I tensorflow/core/framework/local_rendezvous.cc:422] Local rendezvous recv item cancelled. Key hash: 12129038999192260608\n",
      "2024-11-11 13:25:09.060239: I tensorflow/core/framework/local_rendezvous.cc:422] Local rendezvous recv item cancelled. Key hash: 17537048164691407110\n",
      "2024-11-11 13:25:09.060244: W tensorflow/core/framework/local_rendezvous.cc:404] Local rendezvous is aborting with status: UNKNOWN: FileNotFoundError: [Errno 2] No such file or directory: '/Users/code/alzheimerDetect/split_dataset_axial/train/LMCI/Screenshot 2024-08-05 021551.png'\n",
      "Traceback (most recent call last):\n",
      "\n",
      "  File \"/opt/anaconda3/envs/tf_env/lib/python3.9/site-packages/tensorflow/python/ops/script_ops.py\", line 270, in __call__\n",
      "    ret = func(*args)\n",
      "\n",
      "  File \"/opt/anaconda3/envs/tf_env/lib/python3.9/site-packages/tensorflow/python/autograph/impl/api.py\", line 643, in wrapper\n",
      "    return func(*args, **kwargs)\n",
      "\n",
      "  File \"/opt/anaconda3/envs/tf_env/lib/python3.9/site-packages/tensorflow/python/data/ops/from_generator_op.py\", line 198, in generator_py_func\n",
      "    values = next(generator_state.get_iterator(iterator_id))\n",
      "\n",
      "  File \"/opt/anaconda3/envs/tf_env/lib/python3.9/site-packages/keras/src/trainers/data_adapters/py_dataset_adapter.py\", line 260, in _get_iterator\n",
      "    for i, batch in enumerate(gen_fn()):\n",
      "\n",
      "  File \"/opt/anaconda3/envs/tf_env/lib/python3.9/site-packages/keras/src/trainers/data_adapters/py_dataset_adapter.py\", line 253, in generator_fn\n",
      "    yield self.py_dataset[i]\n",
      "\n",
      "  File \"/opt/anaconda3/envs/tf_env/lib/python3.9/site-packages/keras/src/legacy/preprocessing/image.py\", line 68, in __getitem__\n",
      "    return self._get_batches_of_transformed_samples(index_array)\n",
      "\n",
      "  File \"/opt/anaconda3/envs/tf_env/lib/python3.9/site-packages/keras/src/legacy/preprocessing/image.py\", line 313, in _get_batches_of_transformed_samples\n",
      "    img = image_utils.load_img(\n",
      "\n",
      "  File \"/opt/anaconda3/envs/tf_env/lib/python3.9/site-packages/keras/src/utils/image_utils.py\", line 235, in load_img\n",
      "    with open(path, \"rb\") as f:\n",
      "\n",
      "FileNotFoundError: [Errno 2] No such file or directory: '/Users/code/alzheimerDetect/split_dataset_axial/train/LMCI/Screenshot 2024-08-05 021551.png'\n",
      "\n",
      "\n",
      "\t [[{{node PyFunc}}]]\n",
      "\t [[IteratorGetNext]]\n",
      "\t [[StatefulPartitionedCall/adam/add_14/_52]]\n",
      "2024-11-11 13:25:09.060253: I tensorflow/core/framework/local_rendezvous.cc:422] Local rendezvous recv item cancelled. Key hash: 10519956363398026286\n",
      "2024-11-11 13:25:09.060255: I tensorflow/core/framework/local_rendezvous.cc:422] Local rendezvous recv item cancelled. Key hash: 7636598271967014755\n",
      "2024-11-11 13:25:09.060259: I tensorflow/core/framework/local_rendezvous.cc:422] Local rendezvous recv item cancelled. Key hash: 15162237694967042485\n",
      "2024-11-11 13:25:09.060266: I tensorflow/core/framework/local_rendezvous.cc:422] Local rendezvous recv item cancelled. Key hash: 16157401480198025417\n",
      "2024-11-11 13:25:09.060268: I tensorflow/core/framework/local_rendezvous.cc:422] Local rendezvous recv item cancelled. Key hash: 5945813602355043242\n",
      "2024-11-11 13:25:09.060276: I tensorflow/core/framework/local_rendezvous.cc:422] Local rendezvous recv item cancelled. Key hash: 14377770143127862722\n",
      "2024-11-11 13:25:09.060278: I tensorflow/core/framework/local_rendezvous.cc:422] Local rendezvous recv item cancelled. Key hash: 13358348135542482143\n",
      "2024-11-11 13:25:09.060283: I tensorflow/core/framework/local_rendezvous.cc:422] Local rendezvous recv item cancelled. Key hash: 247987022651512771\n",
      "2024-11-11 13:25:09.060285: I tensorflow/core/framework/local_rendezvous.cc:422] Local rendezvous recv item cancelled. Key hash: 10641088503048191638\n",
      "2024-11-11 13:25:09.060288: I tensorflow/core/framework/local_rendezvous.cc:422] Local rendezvous recv item cancelled. Key hash: 8536117531415427311\n",
      "2024-11-11 13:25:09.060292: I tensorflow/core/framework/local_rendezvous.cc:422] Local rendezvous recv item cancelled. Key hash: 11662092417062838046\n",
      "2024-11-11 13:25:09.060296: I tensorflow/core/framework/local_rendezvous.cc:422] Local rendezvous recv item cancelled. Key hash: 13984501884745206167\n",
      "2024-11-11 13:25:09.060299: I tensorflow/core/framework/local_rendezvous.cc:422] Local rendezvous recv item cancelled. Key hash: 9721505157672200855\n",
      "2024-11-11 13:25:09.060304: I tensorflow/core/framework/local_rendezvous.cc:422] Local rendezvous recv item cancelled. Key hash: 16426361773769575293\n",
      "2024-11-11 13:25:09.060308: I tensorflow/core/framework/local_rendezvous.cc:422] Local rendezvous recv item cancelled. Key hash: 9778036480873716785\n",
      "2024-11-11 13:25:09.060311: I tensorflow/core/framework/local_rendezvous.cc:422] Local rendezvous recv item cancelled. Key hash: 9585094191913983771\n"
     ]
    },
    {
     "ename": "UnknownError",
     "evalue": "Graph execution error:\n\nDetected at node PyFunc defined at (most recent call last):\n<stack traces unavailable>\nDetected at node PyFunc defined at (most recent call last):\n<stack traces unavailable>\n2 root error(s) found.\n  (0) UNKNOWN:  FileNotFoundError: [Errno 2] No such file or directory: '/Users/code/alzheimerDetect/split_dataset_axial/train/LMCI/Screenshot 2024-08-05 021551.png'\nTraceback (most recent call last):\n\n  File \"/opt/anaconda3/envs/tf_env/lib/python3.9/site-packages/tensorflow/python/ops/script_ops.py\", line 270, in __call__\n    ret = func(*args)\n\n  File \"/opt/anaconda3/envs/tf_env/lib/python3.9/site-packages/tensorflow/python/autograph/impl/api.py\", line 643, in wrapper\n    return func(*args, **kwargs)\n\n  File \"/opt/anaconda3/envs/tf_env/lib/python3.9/site-packages/tensorflow/python/data/ops/from_generator_op.py\", line 198, in generator_py_func\n    values = next(generator_state.get_iterator(iterator_id))\n\n  File \"/opt/anaconda3/envs/tf_env/lib/python3.9/site-packages/keras/src/trainers/data_adapters/py_dataset_adapter.py\", line 260, in _get_iterator\n    for i, batch in enumerate(gen_fn()):\n\n  File \"/opt/anaconda3/envs/tf_env/lib/python3.9/site-packages/keras/src/trainers/data_adapters/py_dataset_adapter.py\", line 253, in generator_fn\n    yield self.py_dataset[i]\n\n  File \"/opt/anaconda3/envs/tf_env/lib/python3.9/site-packages/keras/src/legacy/preprocessing/image.py\", line 68, in __getitem__\n    return self._get_batches_of_transformed_samples(index_array)\n\n  File \"/opt/anaconda3/envs/tf_env/lib/python3.9/site-packages/keras/src/legacy/preprocessing/image.py\", line 313, in _get_batches_of_transformed_samples\n    img = image_utils.load_img(\n\n  File \"/opt/anaconda3/envs/tf_env/lib/python3.9/site-packages/keras/src/utils/image_utils.py\", line 235, in load_img\n    with open(path, \"rb\") as f:\n\nFileNotFoundError: [Errno 2] No such file or directory: '/Users/code/alzheimerDetect/split_dataset_axial/train/LMCI/Screenshot 2024-08-05 021551.png'\n\n\n\t [[{{node PyFunc}}]]\n\t [[IteratorGetNext]]\n\t [[StatefulPartitionedCall/adam/add_14/_52]]\n  (1) UNKNOWN:  FileNotFoundError: [Errno 2] No such file or directory: '/Users/code/alzheimerDetect/split_dataset_axial/train/LMCI/Screenshot 2024-08-05 021551.png'\nTraceback (most recent call last):\n\n  File \"/opt/anaconda3/envs/tf_env/lib/python3.9/site-packages/tensorflow/python/ops/script_ops.py\", line 270, in __call__\n    ret = func(*args)\n\n  File \"/opt/anaconda3/envs/tf_env/lib/python3.9/site-packages/tensorflow/python/autograph/impl/api.py\", line 643, in wrapper\n    return func(*args, **kwargs)\n\n  File \"/opt/anaconda3/envs/tf_env/lib/python3.9/site-packages/tensorflow/python/data/ops/from_generator_op.py\", line 198, in generator_py_func\n    values = next(generator_state.get_iterator(iterator_id))\n\n  File \"/opt/anaconda3/envs/tf_env/lib/python3.9/site-packages/keras/src/trainers/data_adapters/py_dataset_adapter.py\", line 260, in _get_iterator\n    for i, batch in enumerate(gen_fn()):\n\n  File \"/opt/anaconda3/envs/tf_env/lib/python3.9/site-packages/keras/src/trainers/data_adapters/py_dataset_adapter.py\", line 253, in generator_fn\n    yield self.py_dataset[i]\n\n  File \"/opt/anaconda3/envs/tf_env/lib/python3.9/site-packages/keras/src/legacy/preprocessing/image.py\", line 68, in __getitem__\n    return self._get_batches_of_transformed_samples(index_array)\n\n  File \"/opt/anaconda3/envs/tf_env/lib/python3.9/site-packages/keras/src/legacy/preprocessing/image.py\", line 313, in _get_batches_of_transformed_samples\n    img = image_utils.load_img(\n\n  File \"/opt/anaconda3/envs/tf_env/lib/python3.9/site-packages/keras/src/utils/image_utils.py\", line 235, in load_img\n    with open(path, \"rb\") as f:\n\nFileNotFoundError: [Errno 2] No such file or directory: '/Users/code/alzheimerDetect/split_dataset_axial/train/LMCI/Screenshot 2024-08-05 021551.png'\n\n\n\t [[{{node PyFunc}}]]\n\t [[IteratorGetNext]]\n0 successful operations.\n0 derived errors ignored. [Op:__inference_one_step_on_iterator_2089]",
     "output_type": "error",
     "traceback": [
      "\u001b[0;31m---------------------------------------------------------------------------\u001b[0m",
      "\u001b[0;31mUnknownError\u001b[0m                              Traceback (most recent call last)",
      "Cell \u001b[0;32mIn[1], line 107\u001b[0m\n\u001b[1;32m    102\u001b[0m model\u001b[38;5;241m.\u001b[39mcompile(optimizer\u001b[38;5;241m=\u001b[39m\u001b[38;5;124m'\u001b[39m\u001b[38;5;124madam\u001b[39m\u001b[38;5;124m'\u001b[39m,\n\u001b[1;32m    103\u001b[0m               loss\u001b[38;5;241m=\u001b[39m\u001b[38;5;124m'\u001b[39m\u001b[38;5;124mcategorical_crossentropy\u001b[39m\u001b[38;5;124m'\u001b[39m,\n\u001b[1;32m    104\u001b[0m               metrics\u001b[38;5;241m=\u001b[39m[\u001b[38;5;124m'\u001b[39m\u001b[38;5;124maccuracy\u001b[39m\u001b[38;5;124m'\u001b[39m])\n\u001b[1;32m    106\u001b[0m \u001b[38;5;66;03m# Train the model\u001b[39;00m\n\u001b[0;32m--> 107\u001b[0m history \u001b[38;5;241m=\u001b[39m \u001b[43mmodel\u001b[49m\u001b[38;5;241;43m.\u001b[39;49m\u001b[43mfit\u001b[49m\u001b[43m(\u001b[49m\n\u001b[1;32m    108\u001b[0m \u001b[43m    \u001b[49m\u001b[43mtrain_generator\u001b[49m\u001b[43m,\u001b[49m\n\u001b[1;32m    109\u001b[0m \u001b[43m    \u001b[49m\u001b[43msteps_per_epoch\u001b[49m\u001b[38;5;241;43m=\u001b[39;49m\u001b[43mtrain_generator\u001b[49m\u001b[38;5;241;43m.\u001b[39;49m\u001b[43msamples\u001b[49m\u001b[43m \u001b[49m\u001b[38;5;241;43m/\u001b[39;49m\u001b[38;5;241;43m/\u001b[39;49m\u001b[43m \u001b[49m\u001b[43mtrain_generator\u001b[49m\u001b[38;5;241;43m.\u001b[39;49m\u001b[43mbatch_size\u001b[49m\u001b[43m,\u001b[49m\n\u001b[1;32m    110\u001b[0m \u001b[43m    \u001b[49m\u001b[43mvalidation_data\u001b[49m\u001b[38;5;241;43m=\u001b[39;49m\u001b[43mvalidation_generator\u001b[49m\u001b[43m,\u001b[49m\n\u001b[1;32m    111\u001b[0m \u001b[43m    \u001b[49m\u001b[43mvalidation_steps\u001b[49m\u001b[38;5;241;43m=\u001b[39;49m\u001b[43mvalidation_generator\u001b[49m\u001b[38;5;241;43m.\u001b[39;49m\u001b[43msamples\u001b[49m\u001b[43m \u001b[49m\u001b[38;5;241;43m/\u001b[39;49m\u001b[38;5;241;43m/\u001b[39;49m\u001b[43m \u001b[49m\u001b[43mvalidation_generator\u001b[49m\u001b[38;5;241;43m.\u001b[39;49m\u001b[43mbatch_size\u001b[49m\u001b[43m,\u001b[49m\n\u001b[1;32m    112\u001b[0m \u001b[43m    \u001b[49m\u001b[43mepochs\u001b[49m\u001b[38;5;241;43m=\u001b[39;49m\u001b[38;5;241;43m10\u001b[39;49m\n\u001b[1;32m    113\u001b[0m \u001b[43m)\u001b[49m\n\u001b[1;32m    115\u001b[0m \u001b[38;5;66;03m# Evaluate the model on the test data\u001b[39;00m\n\u001b[1;32m    116\u001b[0m test_loss, test_accuracy \u001b[38;5;241m=\u001b[39m model\u001b[38;5;241m.\u001b[39mevaluate(test_generator)\n",
      "File \u001b[0;32m/opt/anaconda3/envs/tf_env/lib/python3.9/site-packages/keras/src/utils/traceback_utils.py:122\u001b[0m, in \u001b[0;36mfilter_traceback.<locals>.error_handler\u001b[0;34m(*args, **kwargs)\u001b[0m\n\u001b[1;32m    119\u001b[0m     filtered_tb \u001b[38;5;241m=\u001b[39m _process_traceback_frames(e\u001b[38;5;241m.\u001b[39m__traceback__)\n\u001b[1;32m    120\u001b[0m     \u001b[38;5;66;03m# To get the full stack trace, call:\u001b[39;00m\n\u001b[1;32m    121\u001b[0m     \u001b[38;5;66;03m# `keras.config.disable_traceback_filtering()`\u001b[39;00m\n\u001b[0;32m--> 122\u001b[0m     \u001b[38;5;28;01mraise\u001b[39;00m e\u001b[38;5;241m.\u001b[39mwith_traceback(filtered_tb) \u001b[38;5;28;01mfrom\u001b[39;00m \u001b[38;5;28;01mNone\u001b[39;00m\n\u001b[1;32m    123\u001b[0m \u001b[38;5;28;01mfinally\u001b[39;00m:\n\u001b[1;32m    124\u001b[0m     \u001b[38;5;28;01mdel\u001b[39;00m filtered_tb\n",
      "File \u001b[0;32m/opt/anaconda3/envs/tf_env/lib/python3.9/site-packages/tensorflow/python/eager/execute.py:53\u001b[0m, in \u001b[0;36mquick_execute\u001b[0;34m(op_name, num_outputs, inputs, attrs, ctx, name)\u001b[0m\n\u001b[1;32m     51\u001b[0m \u001b[38;5;28;01mtry\u001b[39;00m:\n\u001b[1;32m     52\u001b[0m   ctx\u001b[38;5;241m.\u001b[39mensure_initialized()\n\u001b[0;32m---> 53\u001b[0m   tensors \u001b[38;5;241m=\u001b[39m pywrap_tfe\u001b[38;5;241m.\u001b[39mTFE_Py_Execute(ctx\u001b[38;5;241m.\u001b[39m_handle, device_name, op_name,\n\u001b[1;32m     54\u001b[0m                                       inputs, attrs, num_outputs)\n\u001b[1;32m     55\u001b[0m \u001b[38;5;28;01mexcept\u001b[39;00m core\u001b[38;5;241m.\u001b[39m_NotOkStatusException \u001b[38;5;28;01mas\u001b[39;00m e:\n\u001b[1;32m     56\u001b[0m   \u001b[38;5;28;01mif\u001b[39;00m name \u001b[38;5;129;01mis\u001b[39;00m \u001b[38;5;129;01mnot\u001b[39;00m \u001b[38;5;28;01mNone\u001b[39;00m:\n",
      "\u001b[0;31mUnknownError\u001b[0m: Graph execution error:\n\nDetected at node PyFunc defined at (most recent call last):\n<stack traces unavailable>\nDetected at node PyFunc defined at (most recent call last):\n<stack traces unavailable>\n2 root error(s) found.\n  (0) UNKNOWN:  FileNotFoundError: [Errno 2] No such file or directory: '/Users/code/alzheimerDetect/split_dataset_axial/train/LMCI/Screenshot 2024-08-05 021551.png'\nTraceback (most recent call last):\n\n  File \"/opt/anaconda3/envs/tf_env/lib/python3.9/site-packages/tensorflow/python/ops/script_ops.py\", line 270, in __call__\n    ret = func(*args)\n\n  File \"/opt/anaconda3/envs/tf_env/lib/python3.9/site-packages/tensorflow/python/autograph/impl/api.py\", line 643, in wrapper\n    return func(*args, **kwargs)\n\n  File \"/opt/anaconda3/envs/tf_env/lib/python3.9/site-packages/tensorflow/python/data/ops/from_generator_op.py\", line 198, in generator_py_func\n    values = next(generator_state.get_iterator(iterator_id))\n\n  File \"/opt/anaconda3/envs/tf_env/lib/python3.9/site-packages/keras/src/trainers/data_adapters/py_dataset_adapter.py\", line 260, in _get_iterator\n    for i, batch in enumerate(gen_fn()):\n\n  File \"/opt/anaconda3/envs/tf_env/lib/python3.9/site-packages/keras/src/trainers/data_adapters/py_dataset_adapter.py\", line 253, in generator_fn\n    yield self.py_dataset[i]\n\n  File \"/opt/anaconda3/envs/tf_env/lib/python3.9/site-packages/keras/src/legacy/preprocessing/image.py\", line 68, in __getitem__\n    return self._get_batches_of_transformed_samples(index_array)\n\n  File \"/opt/anaconda3/envs/tf_env/lib/python3.9/site-packages/keras/src/legacy/preprocessing/image.py\", line 313, in _get_batches_of_transformed_samples\n    img = image_utils.load_img(\n\n  File \"/opt/anaconda3/envs/tf_env/lib/python3.9/site-packages/keras/src/utils/image_utils.py\", line 235, in load_img\n    with open(path, \"rb\") as f:\n\nFileNotFoundError: [Errno 2] No such file or directory: '/Users/code/alzheimerDetect/split_dataset_axial/train/LMCI/Screenshot 2024-08-05 021551.png'\n\n\n\t [[{{node PyFunc}}]]\n\t [[IteratorGetNext]]\n\t [[StatefulPartitionedCall/adam/add_14/_52]]\n  (1) UNKNOWN:  FileNotFoundError: [Errno 2] No such file or directory: '/Users/code/alzheimerDetect/split_dataset_axial/train/LMCI/Screenshot 2024-08-05 021551.png'\nTraceback (most recent call last):\n\n  File \"/opt/anaconda3/envs/tf_env/lib/python3.9/site-packages/tensorflow/python/ops/script_ops.py\", line 270, in __call__\n    ret = func(*args)\n\n  File \"/opt/anaconda3/envs/tf_env/lib/python3.9/site-packages/tensorflow/python/autograph/impl/api.py\", line 643, in wrapper\n    return func(*args, **kwargs)\n\n  File \"/opt/anaconda3/envs/tf_env/lib/python3.9/site-packages/tensorflow/python/data/ops/from_generator_op.py\", line 198, in generator_py_func\n    values = next(generator_state.get_iterator(iterator_id))\n\n  File \"/opt/anaconda3/envs/tf_env/lib/python3.9/site-packages/keras/src/trainers/data_adapters/py_dataset_adapter.py\", line 260, in _get_iterator\n    for i, batch in enumerate(gen_fn()):\n\n  File \"/opt/anaconda3/envs/tf_env/lib/python3.9/site-packages/keras/src/trainers/data_adapters/py_dataset_adapter.py\", line 253, in generator_fn\n    yield self.py_dataset[i]\n\n  File \"/opt/anaconda3/envs/tf_env/lib/python3.9/site-packages/keras/src/legacy/preprocessing/image.py\", line 68, in __getitem__\n    return self._get_batches_of_transformed_samples(index_array)\n\n  File \"/opt/anaconda3/envs/tf_env/lib/python3.9/site-packages/keras/src/legacy/preprocessing/image.py\", line 313, in _get_batches_of_transformed_samples\n    img = image_utils.load_img(\n\n  File \"/opt/anaconda3/envs/tf_env/lib/python3.9/site-packages/keras/src/utils/image_utils.py\", line 235, in load_img\n    with open(path, \"rb\") as f:\n\nFileNotFoundError: [Errno 2] No such file or directory: '/Users/code/alzheimerDetect/split_dataset_axial/train/LMCI/Screenshot 2024-08-05 021551.png'\n\n\n\t [[{{node PyFunc}}]]\n\t [[IteratorGetNext]]\n0 successful operations.\n0 derived errors ignored. [Op:__inference_one_step_on_iterator_2089]"
     ]
    }
   ],
   "source": [
    "import tensorflow as tf\n",
    "from tensorflow.keras.preprocessing.image import ImageDataGenerator\n",
    "from tensorflow.keras.models import Sequential\n",
    "from tensorflow.keras.layers import Conv2D, MaxPooling2D, Flatten, Dense, Dropout\n",
    "import os\n",
    "import shutil\n",
    "from sklearn.model_selection import train_test_split\n",
    "\n",
    "# Define directories for original dataset and split dataset\n",
    "original_dataset_dir = '/Users/code/alzheimerDetect/axial'\n",
    "base_dir = '/Users/code/alzheimerDetect/split_dataset_axial'\n",
    "train_dir = os.path.join(base_dir, 'train')\n",
    "test_dir = os.path.join(base_dir, 'test')\n",
    "\n",
    "# Define categories\n",
    "categories = ['AD', 'CN', 'EMCI', 'LMCI']\n",
    "\n",
    "# Clear old directories if they exist, then create new directories for training and testing data\n",
    "if os.path.exists(base_dir):\n",
    "    shutil.rmtree(base_dir)\n",
    "os.makedirs(train_dir, exist_ok=True)\n",
    "os.makedirs(test_dir, exist_ok=True)\n",
    "\n",
    "for category in categories:\n",
    "    os.makedirs(os.path.join(train_dir, category), exist_ok=True)\n",
    "    os.makedirs(os.path.join(test_dir, category), exist_ok=True)\n",
    "\n",
    "    # List files in the category directory\n",
    "    category_dir = os.path.join(original_dataset_dir, category)\n",
    "    files = os.listdir(category_dir)\n",
    "    \n",
    "    # Split the data\n",
    "    train_files, test_files = train_test_split(files, test_size=0.2, random_state=42)\n",
    "    \n",
    "    # Copy files to train directory\n",
    "    for file in train_files:\n",
    "        src = os.path.join(category_dir, file)\n",
    "        dst = os.path.join(train_dir, category, file)\n",
    "        shutil.copyfile(src, dst)\n",
    "    \n",
    "    # Copy files to test directory\n",
    "    for file in test_files:\n",
    "        src = os.path.join(category_dir, file)\n",
    "        dst = os.path.join(test_dir, category, file)\n",
    "        shutil.copyfile(src, dst)\n",
    "\n",
    "print(\"Dataset split into training and testing sets.\")\n",
    "\n",
    "# Data Preprocessing\n",
    "train_datagen = ImageDataGenerator(\n",
    "    rescale=1/255.0,\n",
    "    validation_split=0.2  # 20% of the data will be used for validation\n",
    ")\n",
    "\n",
    "test_datagen = ImageDataGenerator(\n",
    "    rescale=1/255.0\n",
    ")\n",
    "\n",
    "# Load training data and validation data from the training directory\n",
    "train_generator = train_datagen.flow_from_directory(\n",
    "    train_dir,\n",
    "    target_size=(150, 150),  # Resize images to 150x150 pixels\n",
    "    batch_size=32,\n",
    "    class_mode='categorical',  # Multi-class classification\n",
    "    subset='training'  # Set as training data\n",
    ")\n",
    "\n",
    "validation_generator = train_datagen.flow_from_directory(\n",
    "    train_dir,\n",
    "    target_size=(150, 150),\n",
    "    batch_size=32,\n",
    "    class_mode='categorical',  # Multi-class classification\n",
    "    subset='validation'  # Set as validation data\n",
    ")\n",
    "\n",
    "# Load test data from the test directory\n",
    "test_generator = test_datagen.flow_from_directory(\n",
    "    test_dir,\n",
    "    target_size=(150, 150),\n",
    "    batch_size=32,\n",
    "    class_mode='categorical'  # Multi-class classification\n",
    ")\n",
    "\n",
    "# Print the class indices to verify correct classes\n",
    "print(\"Class indices:\", train_generator.class_indices)\n",
    "\n",
    "# Build the model\n",
    "model = Sequential([\n",
    "    Conv2D(32, (3, 3), activation='relu', input_shape=(150, 150, 3)),\n",
    "    MaxPooling2D(2, 2),\n",
    "    Conv2D(64, (3, 3), activation='relu'),\n",
    "    MaxPooling2D(2, 2),\n",
    "    Conv2D(128, (3, 3), activation='relu'),\n",
    "    MaxPooling2D(2, 2),\n",
    "    Flatten(),\n",
    "    Dense(512, activation='relu'),\n",
    "    Dropout(0.5),\n",
    "    Dense(len(categories), activation='softmax')  # Output layer for multi-class classification\n",
    "])\n",
    "\n",
    "# Compile the model\n",
    "model.compile(optimizer='adam',\n",
    "              loss='categorical_crossentropy',\n",
    "              metrics=['accuracy'])\n",
    "\n",
    "# Train the model\n",
    "history = model.fit(\n",
    "    train_generator,\n",
    "    steps_per_epoch=train_generator.samples // train_generator.batch_size,\n",
    "    validation_data=validation_generator,\n",
    "    validation_steps=validation_generator.samples // validation_generator.batch_size,\n",
    "    epochs=10\n",
    ")\n",
    "\n",
    "# Evaluate the model on the test data\n",
    "test_loss, test_accuracy = model.evaluate(test_generator)\n",
    "print(f\"Test accuracy: {test_accuracy:.2f}\")"
   ]
  },
  {
   "cell_type": "code",
   "execution_count": null,
   "id": "87b0675c-dfa1-4430-bccd-fdfabb761933",
   "metadata": {},
   "outputs": [],
   "source": []
  }
 ],
 "metadata": {
  "kernelspec": {
   "display_name": "Python 3 (ipykernel)",
   "language": "python",
   "name": "python3"
  },
  "language_info": {
   "codemirror_mode": {
    "name": "ipython",
    "version": 3
   },
   "file_extension": ".py",
   "mimetype": "text/x-python",
   "name": "python",
   "nbconvert_exporter": "python",
   "pygments_lexer": "ipython3",
   "version": "3.9.19"
  }
 },
 "nbformat": 4,
 "nbformat_minor": 5
}
